<?xml version="1.0" ?>
<testsuite name="unittest.loader._FailedTest-20220923173409" tests="39" time="0.001" failures="0" errors="39">
	<testcase classname="unittest.loader._FailedTest" name="asposecellscloud" time="0.000">
		<error type="ImportError" message="Failed to import test module: asposecellscloud
Traceback (most recent call last):
  File &quot;C:\Users\Cells\AppData\Local\Programs\Python\Python310\lib\unittest\loader.py&quot;, line 470, in _find_test_path
    package = self._get_module_from_name(name)
  File &quot;C:\Users\Cells\AppData\Local\Programs\Python\Python310\lib\unittest\loader.py&quot;, line 377, in _get_module_from_name
    __import__(name)
  File &quot;D:\aspose\cells\cloud\sdk-python\asposecellscloud\__init__.py&quot;, line 27, in &lt;module&gt;
    from .models.above_average import AboveAverage
  File &quot;D:\aspose\cells\cloud\sdk-python\asposecellscloud\models\__init__.py&quot;, line 27, in &lt;module&gt;
    from .above_average import AboveAverage
  File &quot;D:\aspose\cells\cloud\sdk-python\asposecellscloud\models\above_average.py&quot;, line 25, in &lt;module&gt;
    from six import iteritems
ModuleNotFoundError: No module named 'six'
"><![CDATA[ImportError: Failed to import test module: asposecellscloud
Traceback (most recent call last):
  File "C:\Users\Cells\AppData\Local\Programs\Python\Python310\lib\unittest\loader.py", line 470, in _find_test_path
    package = self._get_module_from_name(name)
  File "C:\Users\Cells\AppData\Local\Programs\Python\Python310\lib\unittest\loader.py", line 377, in _get_module_from_name
    __import__(name)
  File "D:\aspose\cells\cloud\sdk-python\asposecellscloud\__init__.py", line 27, in <module>
    from .models.above_average import AboveAverage
  File "D:\aspose\cells\cloud\sdk-python\asposecellscloud\models\__init__.py", line 27, in <module>
    from .above_average import AboveAverage
  File "D:\aspose\cells\cloud\sdk-python\asposecellscloud\models\above_average.py", line 25, in <module>
    from six import iteritems
ModuleNotFoundError: No module named 'six'

]]></error>
	</testcase>
	<testcase classname="unittest.loader._FailedTest" name="test_cells_api" time="0.000">
		<error type="ImportError" message="Failed to import test module: test.test_cells_api
Traceback (most recent call last):
  File &quot;C:\Users\Cells\AppData\Local\Programs\Python\Python310\lib\unittest\loader.py&quot;, line 436, in _find_test_path
    module = self._get_module_from_name(name)
  File &quot;C:\Users\Cells\AppData\Local\Programs\Python\Python310\lib\unittest\loader.py&quot;, line 377, in _get_module_from_name
    __import__(name)
  File &quot;D:\aspose\cells\cloud\sdk-python\test\test_cells_api.py&quot;, line 12, in &lt;module&gt;
    import asposecellscloud
  File &quot;D:\aspose\cells\cloud\sdk-python\asposecellscloud\__init__.py&quot;, line 27, in &lt;module&gt;
    from .models.above_average import AboveAverage
  File &quot;D:\aspose\cells\cloud\sdk-python\asposecellscloud\models\__init__.py&quot;, line 27, in &lt;module&gt;
    from .above_average import AboveAverage
  File &quot;D:\aspose\cells\cloud\sdk-python\asposecellscloud\models\above_average.py&quot;, line 25, in &lt;module&gt;
    from six import iteritems
ModuleNotFoundError: No module named 'six'
"><![CDATA[ImportError: Failed to import test module: test.test_cells_api
Traceback (most recent call last):
  File "C:\Users\Cells\AppData\Local\Programs\Python\Python310\lib\unittest\loader.py", line 436, in _find_test_path
    module = self._get_module_from_name(name)
  File "C:\Users\Cells\AppData\Local\Programs\Python\Python310\lib\unittest\loader.py", line 377, in _get_module_from_name
    __import__(name)
  File "D:\aspose\cells\cloud\sdk-python\test\test_cells_api.py", line 12, in <module>
    import asposecellscloud
  File "D:\aspose\cells\cloud\sdk-python\asposecellscloud\__init__.py", line 27, in <module>
    from .models.above_average import AboveAverage
  File "D:\aspose\cells\cloud\sdk-python\asposecellscloud\models\__init__.py", line 27, in <module>
    from .above_average import AboveAverage
  File "D:\aspose\cells\cloud\sdk-python\asposecellscloud\models\above_average.py", line 25, in <module>
    from six import iteritems
ModuleNotFoundError: No module named 'six'

]]></error>
	</testcase>
	<testcase classname="unittest.loader._FailedTest" name="test_cells_assembly_api" time="0.000">
		<error type="ImportError" message="Failed to import test module: test.test_cells_assembly_api
Traceback (most recent call last):
  File &quot;C:\Users\Cells\AppData\Local\Programs\Python\Python310\lib\unittest\loader.py&quot;, line 436, in _find_test_path
    module = self._get_module_from_name(name)
  File &quot;C:\Users\Cells\AppData\Local\Programs\Python\Python310\lib\unittest\loader.py&quot;, line 377, in _get_module_from_name
    __import__(name)
  File &quot;D:\aspose\cells\cloud\sdk-python\test\test_cells_assembly_api.py&quot;, line 12, in &lt;module&gt;
    import asposecellscloud
  File &quot;D:\aspose\cells\cloud\sdk-python\asposecellscloud\__init__.py&quot;, line 27, in &lt;module&gt;
    from .models.above_average import AboveAverage
  File &quot;D:\aspose\cells\cloud\sdk-python\asposecellscloud\models\__init__.py&quot;, line 27, in &lt;module&gt;
    from .above_average import AboveAverage
  File &quot;D:\aspose\cells\cloud\sdk-python\asposecellscloud\models\above_average.py&quot;, line 25, in &lt;module&gt;
    from six import iteritems
ModuleNotFoundError: No module named 'six'
"><![CDATA[ImportError: Failed to import test module: test.test_cells_assembly_api
Traceback (most recent call last):
  File "C:\Users\Cells\AppData\Local\Programs\Python\Python310\lib\unittest\loader.py", line 436, in _find_test_path
    module = self._get_module_from_name(name)
  File "C:\Users\Cells\AppData\Local\Programs\Python\Python310\lib\unittest\loader.py", line 377, in _get_module_from_name
    __import__(name)
  File "D:\aspose\cells\cloud\sdk-python\test\test_cells_assembly_api.py", line 12, in <module>
    import asposecellscloud
  File "D:\aspose\cells\cloud\sdk-python\asposecellscloud\__init__.py", line 27, in <module>
    from .models.above_average import AboveAverage
  File "D:\aspose\cells\cloud\sdk-python\asposecellscloud\models\__init__.py", line 27, in <module>
    from .above_average import AboveAverage
  File "D:\aspose\cells\cloud\sdk-python\asposecellscloud\models\above_average.py", line 25, in <module>
    from six import iteritems
ModuleNotFoundError: No module named 'six'

]]></error>
	</testcase>
	<testcase classname="unittest.loader._FailedTest" name="test_cells_auto_filter_api" time="0.000">
		<error type="ImportError" message="Failed to import test module: test.test_cells_auto_filter_api
Traceback (most recent call last):
  File &quot;C:\Users\Cells\AppData\Local\Programs\Python\Python310\lib\unittest\loader.py&quot;, line 436, in _find_test_path
    module = self._get_module_from_name(name)
  File &quot;C:\Users\Cells\AppData\Local\Programs\Python\Python310\lib\unittest\loader.py&quot;, line 377, in _get_module_from_name
    __import__(name)
  File &quot;D:\aspose\cells\cloud\sdk-python\test\test_cells_auto_filter_api.py&quot;, line 23, in &lt;module&gt;
    import asposecellscloud
  File &quot;D:\aspose\cells\cloud\sdk-python\asposecellscloud\__init__.py&quot;, line 27, in &lt;module&gt;
    from .models.above_average import AboveAverage
  File &quot;D:\aspose\cells\cloud\sdk-python\asposecellscloud\models\__init__.py&quot;, line 27, in &lt;module&gt;
    from .above_average import AboveAverage
  File &quot;D:\aspose\cells\cloud\sdk-python\asposecellscloud\models\above_average.py&quot;, line 25, in &lt;module&gt;
    from six import iteritems
ModuleNotFoundError: No module named 'six'
"><![CDATA[ImportError: Failed to import test module: test.test_cells_auto_filter_api
Traceback (most recent call last):
  File "C:\Users\Cells\AppData\Local\Programs\Python\Python310\lib\unittest\loader.py", line 436, in _find_test_path
    module = self._get_module_from_name(name)
  File "C:\Users\Cells\AppData\Local\Programs\Python\Python310\lib\unittest\loader.py", line 377, in _get_module_from_name
    __import__(name)
  File "D:\aspose\cells\cloud\sdk-python\test\test_cells_auto_filter_api.py", line 23, in <module>
    import asposecellscloud
  File "D:\aspose\cells\cloud\sdk-python\asposecellscloud\__init__.py", line 27, in <module>
    from .models.above_average import AboveAverage
  File "D:\aspose\cells\cloud\sdk-python\asposecellscloud\models\__init__.py", line 27, in <module>
    from .above_average import AboveAverage
  File "D:\aspose\cells\cloud\sdk-python\asposecellscloud\models\above_average.py", line 25, in <module>
    from six import iteritems
ModuleNotFoundError: No module named 'six'

]]></error>
	</testcase>
	<testcase classname="unittest.loader._FailedTest" name="test_cells_autoshapes_api" time="0.000">
		<error type="ImportError" message="Failed to import test module: test.test_cells_autoshapes_api
Traceback (most recent call last):
  File &quot;C:\Users\Cells\AppData\Local\Programs\Python\Python310\lib\unittest\loader.py&quot;, line 436, in _find_test_path
    module = self._get_module_from_name(name)
  File &quot;C:\Users\Cells\AppData\Local\Programs\Python\Python310\lib\unittest\loader.py&quot;, line 377, in _get_module_from_name
    __import__(name)
  File &quot;D:\aspose\cells\cloud\sdk-python\test\test_cells_autoshapes_api.py&quot;, line 12, in &lt;module&gt;
    import asposecellscloud
  File &quot;D:\aspose\cells\cloud\sdk-python\asposecellscloud\__init__.py&quot;, line 27, in &lt;module&gt;
    from .models.above_average import AboveAverage
  File &quot;D:\aspose\cells\cloud\sdk-python\asposecellscloud\models\__init__.py&quot;, line 27, in &lt;module&gt;
    from .above_average import AboveAverage
  File &quot;D:\aspose\cells\cloud\sdk-python\asposecellscloud\models\above_average.py&quot;, line 25, in &lt;module&gt;
    from six import iteritems
ModuleNotFoundError: No module named 'six'
"><![CDATA[ImportError: Failed to import test module: test.test_cells_autoshapes_api
Traceback (most recent call last):
  File "C:\Users\Cells\AppData\Local\Programs\Python\Python310\lib\unittest\loader.py", line 436, in _find_test_path
    module = self._get_module_from_name(name)
  File "C:\Users\Cells\AppData\Local\Programs\Python\Python310\lib\unittest\loader.py", line 377, in _get_module_from_name
    __import__(name)
  File "D:\aspose\cells\cloud\sdk-python\test\test_cells_autoshapes_api.py", line 12, in <module>
    import asposecellscloud
  File "D:\aspose\cells\cloud\sdk-python\asposecellscloud\__init__.py", line 27, in <module>
    from .models.above_average import AboveAverage
  File "D:\aspose\cells\cloud\sdk-python\asposecellscloud\models\__init__.py", line 27, in <module>
    from .above_average import AboveAverage
  File "D:\aspose\cells\cloud\sdk-python\asposecellscloud\models\above_average.py", line 25, in <module>
    from six import iteritems
ModuleNotFoundError: No module named 'six'

]]></error>
	</testcase>
	<testcase classname="unittest.loader._FailedTest" name="test_cells_barcode_api" time="0.000">
		<error type="ImportError" message="Failed to import test module: test.test_cells_barcode_api
Traceback (most recent call last):
  File &quot;C:\Users\Cells\AppData\Local\Programs\Python\Python310\lib\unittest\loader.py&quot;, line 436, in _find_test_path
    module = self._get_module_from_name(name)
  File &quot;C:\Users\Cells\AppData\Local\Programs\Python\Python310\lib\unittest\loader.py&quot;, line 377, in _get_module_from_name
    __import__(name)
  File &quot;D:\aspose\cells\cloud\sdk-python\test\test_cells_barcode_api.py&quot;, line 23, in &lt;module&gt;
    import asposecellscloud
  File &quot;D:\aspose\cells\cloud\sdk-python\asposecellscloud\__init__.py&quot;, line 27, in &lt;module&gt;
    from .models.above_average import AboveAverage
  File &quot;D:\aspose\cells\cloud\sdk-python\asposecellscloud\models\__init__.py&quot;, line 27, in &lt;module&gt;
    from .above_average import AboveAverage
  File &quot;D:\aspose\cells\cloud\sdk-python\asposecellscloud\models\above_average.py&quot;, line 25, in &lt;module&gt;
    from six import iteritems
ModuleNotFoundError: No module named 'six'
"><![CDATA[ImportError: Failed to import test module: test.test_cells_barcode_api
Traceback (most recent call last):
  File "C:\Users\Cells\AppData\Local\Programs\Python\Python310\lib\unittest\loader.py", line 436, in _find_test_path
    module = self._get_module_from_name(name)
  File "C:\Users\Cells\AppData\Local\Programs\Python\Python310\lib\unittest\loader.py", line 377, in _get_module_from_name
    __import__(name)
  File "D:\aspose\cells\cloud\sdk-python\test\test_cells_barcode_api.py", line 23, in <module>
    import asposecellscloud
  File "D:\aspose\cells\cloud\sdk-python\asposecellscloud\__init__.py", line 27, in <module>
    from .models.above_average import AboveAverage
  File "D:\aspose\cells\cloud\sdk-python\asposecellscloud\models\__init__.py", line 27, in <module>
    from .above_average import AboveAverage
  File "D:\aspose\cells\cloud\sdk-python\asposecellscloud\models\above_average.py", line 25, in <module>
    from six import iteritems
ModuleNotFoundError: No module named 'six'

]]></error>
	</testcase>
	<testcase classname="unittest.loader._FailedTest" name="test_cells_batch_api" time="0.000">
		<error type="ImportError" message="Failed to import test module: test.test_cells_batch_api
Traceback (most recent call last):
  File &quot;C:\Users\Cells\AppData\Local\Programs\Python\Python310\lib\unittest\loader.py&quot;, line 436, in _find_test_path
    module = self._get_module_from_name(name)
  File &quot;C:\Users\Cells\AppData\Local\Programs\Python\Python310\lib\unittest\loader.py&quot;, line 377, in _get_module_from_name
    __import__(name)
  File &quot;D:\aspose\cells\cloud\sdk-python\test\test_cells_batch_api.py&quot;, line 23, in &lt;module&gt;
    import asposecellscloud
  File &quot;D:\aspose\cells\cloud\sdk-python\asposecellscloud\__init__.py&quot;, line 27, in &lt;module&gt;
    from .models.above_average import AboveAverage
  File &quot;D:\aspose\cells\cloud\sdk-python\asposecellscloud\models\__init__.py&quot;, line 27, in &lt;module&gt;
    from .above_average import AboveAverage
  File &quot;D:\aspose\cells\cloud\sdk-python\asposecellscloud\models\above_average.py&quot;, line 25, in &lt;module&gt;
    from six import iteritems
ModuleNotFoundError: No module named 'six'
"><![CDATA[ImportError: Failed to import test module: test.test_cells_batch_api
Traceback (most recent call last):
  File "C:\Users\Cells\AppData\Local\Programs\Python\Python310\lib\unittest\loader.py", line 436, in _find_test_path
    module = self._get_module_from_name(name)
  File "C:\Users\Cells\AppData\Local\Programs\Python\Python310\lib\unittest\loader.py", line 377, in _get_module_from_name
    __import__(name)
  File "D:\aspose\cells\cloud\sdk-python\test\test_cells_batch_api.py", line 23, in <module>
    import asposecellscloud
  File "D:\aspose\cells\cloud\sdk-python\asposecellscloud\__init__.py", line 27, in <module>
    from .models.above_average import AboveAverage
  File "D:\aspose\cells\cloud\sdk-python\asposecellscloud\models\__init__.py", line 27, in <module>
    from .above_average import AboveAverage
  File "D:\aspose\cells\cloud\sdk-python\asposecellscloud\models\above_average.py", line 25, in <module>
    from six import iteritems
ModuleNotFoundError: No module named 'six'

]]></error>
	</testcase>
	<testcase classname="unittest.loader._FailedTest" name="test_cells_chart_area_api" time="0.000">
		<error type="ImportError" message="Failed to import test module: test.test_cells_chart_area_api
Traceback (most recent call last):
  File &quot;C:\Users\Cells\AppData\Local\Programs\Python\Python310\lib\unittest\loader.py&quot;, line 436, in _find_test_path
    module = self._get_module_from_name(name)
  File &quot;C:\Users\Cells\AppData\Local\Programs\Python\Python310\lib\unittest\loader.py&quot;, line 377, in _get_module_from_name
    __import__(name)
  File &quot;D:\aspose\cells\cloud\sdk-python\test\test_cells_chart_area_api.py&quot;, line 23, in &lt;module&gt;
    import asposecellscloud
  File &quot;D:\aspose\cells\cloud\sdk-python\asposecellscloud\__init__.py&quot;, line 27, in &lt;module&gt;
    from .models.above_average import AboveAverage
  File &quot;D:\aspose\cells\cloud\sdk-python\asposecellscloud\models\__init__.py&quot;, line 27, in &lt;module&gt;
    from .above_average import AboveAverage
  File &quot;D:\aspose\cells\cloud\sdk-python\asposecellscloud\models\above_average.py&quot;, line 25, in &lt;module&gt;
    from six import iteritems
ModuleNotFoundError: No module named 'six'
"><![CDATA[ImportError: Failed to import test module: test.test_cells_chart_area_api
Traceback (most recent call last):
  File "C:\Users\Cells\AppData\Local\Programs\Python\Python310\lib\unittest\loader.py", line 436, in _find_test_path
    module = self._get_module_from_name(name)
  File "C:\Users\Cells\AppData\Local\Programs\Python\Python310\lib\unittest\loader.py", line 377, in _get_module_from_name
    __import__(name)
  File "D:\aspose\cells\cloud\sdk-python\test\test_cells_chart_area_api.py", line 23, in <module>
    import asposecellscloud
  File "D:\aspose\cells\cloud\sdk-python\asposecellscloud\__init__.py", line 27, in <module>
    from .models.above_average import AboveAverage
  File "D:\aspose\cells\cloud\sdk-python\asposecellscloud\models\__init__.py", line 27, in <module>
    from .above_average import AboveAverage
  File "D:\aspose\cells\cloud\sdk-python\asposecellscloud\models\above_average.py", line 25, in <module>
    from six import iteritems
ModuleNotFoundError: No module named 'six'

]]></error>
	</testcase>
	<testcase classname="unittest.loader._FailedTest" name="test_cells_charts_api" time="0.000">
		<error type="ImportError" message="Failed to import test module: test.test_cells_charts_api
Traceback (most recent call last):
  File &quot;C:\Users\Cells\AppData\Local\Programs\Python\Python310\lib\unittest\loader.py&quot;, line 436, in _find_test_path
    module = self._get_module_from_name(name)
  File &quot;C:\Users\Cells\AppData\Local\Programs\Python\Python310\lib\unittest\loader.py&quot;, line 377, in _get_module_from_name
    __import__(name)
  File &quot;D:\aspose\cells\cloud\sdk-python\test\test_cells_charts_api.py&quot;, line 23, in &lt;module&gt;
    import asposecellscloud
  File &quot;D:\aspose\cells\cloud\sdk-python\asposecellscloud\__init__.py&quot;, line 27, in &lt;module&gt;
    from .models.above_average import AboveAverage
  File &quot;D:\aspose\cells\cloud\sdk-python\asposecellscloud\models\__init__.py&quot;, line 27, in &lt;module&gt;
    from .above_average import AboveAverage
  File &quot;D:\aspose\cells\cloud\sdk-python\asposecellscloud\models\above_average.py&quot;, line 25, in &lt;module&gt;
    from six import iteritems
ModuleNotFoundError: No module named 'six'
"><![CDATA[ImportError: Failed to import test module: test.test_cells_charts_api
Traceback (most recent call last):
  File "C:\Users\Cells\AppData\Local\Programs\Python\Python310\lib\unittest\loader.py", line 436, in _find_test_path
    module = self._get_module_from_name(name)
  File "C:\Users\Cells\AppData\Local\Programs\Python\Python310\lib\unittest\loader.py", line 377, in _get_module_from_name
    __import__(name)
  File "D:\aspose\cells\cloud\sdk-python\test\test_cells_charts_api.py", line 23, in <module>
    import asposecellscloud
  File "D:\aspose\cells\cloud\sdk-python\asposecellscloud\__init__.py", line 27, in <module>
    from .models.above_average import AboveAverage
  File "D:\aspose\cells\cloud\sdk-python\asposecellscloud\models\__init__.py", line 27, in <module>
    from .above_average import AboveAverage
  File "D:\aspose\cells\cloud\sdk-python\asposecellscloud\models\above_average.py", line 25, in <module>
    from six import iteritems
ModuleNotFoundError: No module named 'six'

]]></error>
	</testcase>
	<testcase classname="unittest.loader._FailedTest" name="test_cells_clear_object_api" time="0.000">
		<error type="ImportError" message="Failed to import test module: test.test_cells_clear_object_api
Traceback (most recent call last):
  File &quot;C:\Users\Cells\AppData\Local\Programs\Python\Python310\lib\unittest\loader.py&quot;, line 436, in _find_test_path
    module = self._get_module_from_name(name)
  File &quot;C:\Users\Cells\AppData\Local\Programs\Python\Python310\lib\unittest\loader.py&quot;, line 377, in _get_module_from_name
    __import__(name)
  File &quot;D:\aspose\cells\cloud\sdk-python\test\test_cells_clear_object_api.py&quot;, line 12, in &lt;module&gt;
    import asposecellscloud
  File &quot;D:\aspose\cells\cloud\sdk-python\asposecellscloud\__init__.py&quot;, line 27, in &lt;module&gt;
    from .models.above_average import AboveAverage
  File &quot;D:\aspose\cells\cloud\sdk-python\asposecellscloud\models\__init__.py&quot;, line 27, in &lt;module&gt;
    from .above_average import AboveAverage
  File &quot;D:\aspose\cells\cloud\sdk-python\asposecellscloud\models\above_average.py&quot;, line 25, in &lt;module&gt;
    from six import iteritems
ModuleNotFoundError: No module named 'six'
"><![CDATA[ImportError: Failed to import test module: test.test_cells_clear_object_api
Traceback (most recent call last):
  File "C:\Users\Cells\AppData\Local\Programs\Python\Python310\lib\unittest\loader.py", line 436, in _find_test_path
    module = self._get_module_from_name(name)
  File "C:\Users\Cells\AppData\Local\Programs\Python\Python310\lib\unittest\loader.py", line 377, in _get_module_from_name
    __import__(name)
  File "D:\aspose\cells\cloud\sdk-python\test\test_cells_clear_object_api.py", line 12, in <module>
    import asposecellscloud
  File "D:\aspose\cells\cloud\sdk-python\asposecellscloud\__init__.py", line 27, in <module>
    from .models.above_average import AboveAverage
  File "D:\aspose\cells\cloud\sdk-python\asposecellscloud\models\__init__.py", line 27, in <module>
    from .above_average import AboveAverage
  File "D:\aspose\cells\cloud\sdk-python\asposecellscloud\models\above_average.py", line 25, in <module>
    from six import iteritems
ModuleNotFoundError: No module named 'six'

]]></error>
	</testcase>
	<testcase classname="unittest.loader._FailedTest" name="test_cells_compress_api" time="0.000">
		<error type="ImportError" message="Failed to import test module: test.test_cells_compress_api
Traceback (most recent call last):
  File &quot;C:\Users\Cells\AppData\Local\Programs\Python\Python310\lib\unittest\loader.py&quot;, line 436, in _find_test_path
    module = self._get_module_from_name(name)
  File &quot;C:\Users\Cells\AppData\Local\Programs\Python\Python310\lib\unittest\loader.py&quot;, line 377, in _get_module_from_name
    __import__(name)
  File &quot;D:\aspose\cells\cloud\sdk-python\test\test_cells_compress_api.py&quot;, line 12, in &lt;module&gt;
    import asposecellscloud
  File &quot;D:\aspose\cells\cloud\sdk-python\asposecellscloud\__init__.py&quot;, line 27, in &lt;module&gt;
    from .models.above_average import AboveAverage
  File &quot;D:\aspose\cells\cloud\sdk-python\asposecellscloud\models\__init__.py&quot;, line 27, in &lt;module&gt;
    from .above_average import AboveAverage
  File &quot;D:\aspose\cells\cloud\sdk-python\asposecellscloud\models\above_average.py&quot;, line 25, in &lt;module&gt;
    from six import iteritems
ModuleNotFoundError: No module named 'six'
"><![CDATA[ImportError: Failed to import test module: test.test_cells_compress_api
Traceback (most recent call last):
  File "C:\Users\Cells\AppData\Local\Programs\Python\Python310\lib\unittest\loader.py", line 436, in _find_test_path
    module = self._get_module_from_name(name)
  File "C:\Users\Cells\AppData\Local\Programs\Python\Python310\lib\unittest\loader.py", line 377, in _get_module_from_name
    __import__(name)
  File "D:\aspose\cells\cloud\sdk-python\test\test_cells_compress_api.py", line 12, in <module>
    import asposecellscloud
  File "D:\aspose\cells\cloud\sdk-python\asposecellscloud\__init__.py", line 27, in <module>
    from .models.above_average import AboveAverage
  File "D:\aspose\cells\cloud\sdk-python\asposecellscloud\models\__init__.py", line 27, in <module>
    from .above_average import AboveAverage
  File "D:\aspose\cells\cloud\sdk-python\asposecellscloud\models\above_average.py", line 25, in <module>
    from six import iteritems
ModuleNotFoundError: No module named 'six'

]]></error>
	</testcase>
	<testcase classname="unittest.loader._FailedTest" name="test_cells_conditional_formattings_api" time="0.000">
		<error type="ImportError" message="Failed to import test module: test.test_cells_conditional_formattings_api
Traceback (most recent call last):
  File &quot;C:\Users\Cells\AppData\Local\Programs\Python\Python310\lib\unittest\loader.py&quot;, line 436, in _find_test_path
    module = self._get_module_from_name(name)
  File &quot;C:\Users\Cells\AppData\Local\Programs\Python\Python310\lib\unittest\loader.py&quot;, line 377, in _get_module_from_name
    __import__(name)
  File &quot;D:\aspose\cells\cloud\sdk-python\test\test_cells_conditional_formattings_api.py&quot;, line 23, in &lt;module&gt;
    import asposecellscloud
  File &quot;D:\aspose\cells\cloud\sdk-python\asposecellscloud\__init__.py&quot;, line 27, in &lt;module&gt;
    from .models.above_average import AboveAverage
  File &quot;D:\aspose\cells\cloud\sdk-python\asposecellscloud\models\__init__.py&quot;, line 27, in &lt;module&gt;
    from .above_average import AboveAverage
  File &quot;D:\aspose\cells\cloud\sdk-python\asposecellscloud\models\above_average.py&quot;, line 25, in &lt;module&gt;
    from six import iteritems
ModuleNotFoundError: No module named 'six'
"><![CDATA[ImportError: Failed to import test module: test.test_cells_conditional_formattings_api
Traceback (most recent call last):
  File "C:\Users\Cells\AppData\Local\Programs\Python\Python310\lib\unittest\loader.py", line 436, in _find_test_path
    module = self._get_module_from_name(name)
  File "C:\Users\Cells\AppData\Local\Programs\Python\Python310\lib\unittest\loader.py", line 377, in _get_module_from_name
    __import__(name)
  File "D:\aspose\cells\cloud\sdk-python\test\test_cells_conditional_formattings_api.py", line 23, in <module>
    import asposecellscloud
  File "D:\aspose\cells\cloud\sdk-python\asposecellscloud\__init__.py", line 27, in <module>
    from .models.above_average import AboveAverage
  File "D:\aspose\cells\cloud\sdk-python\asposecellscloud\models\__init__.py", line 27, in <module>
    from .above_average import AboveAverage
  File "D:\aspose\cells\cloud\sdk-python\asposecellscloud\models\above_average.py", line 25, in <module>
    from six import iteritems
ModuleNotFoundError: No module named 'six'

]]></error>
	</testcase>
	<testcase classname="unittest.loader._FailedTest" name="test_cells_export_object_api" time="0.000">
		<error type="ImportError" message="Failed to import test module: test.test_cells_export_object_api
Traceback (most recent call last):
  File &quot;C:\Users\Cells\AppData\Local\Programs\Python\Python310\lib\unittest\loader.py&quot;, line 436, in _find_test_path
    module = self._get_module_from_name(name)
  File &quot;C:\Users\Cells\AppData\Local\Programs\Python\Python310\lib\unittest\loader.py&quot;, line 377, in _get_module_from_name
    __import__(name)
  File &quot;D:\aspose\cells\cloud\sdk-python\test\test_cells_export_object_api.py&quot;, line 12, in &lt;module&gt;
    import asposecellscloud
  File &quot;D:\aspose\cells\cloud\sdk-python\asposecellscloud\__init__.py&quot;, line 27, in &lt;module&gt;
    from .models.above_average import AboveAverage
  File &quot;D:\aspose\cells\cloud\sdk-python\asposecellscloud\models\__init__.py&quot;, line 27, in &lt;module&gt;
    from .above_average import AboveAverage
  File &quot;D:\aspose\cells\cloud\sdk-python\asposecellscloud\models\above_average.py&quot;, line 25, in &lt;module&gt;
    from six import iteritems
ModuleNotFoundError: No module named 'six'
"><![CDATA[ImportError: Failed to import test module: test.test_cells_export_object_api
Traceback (most recent call last):
  File "C:\Users\Cells\AppData\Local\Programs\Python\Python310\lib\unittest\loader.py", line 436, in _find_test_path
    module = self._get_module_from_name(name)
  File "C:\Users\Cells\AppData\Local\Programs\Python\Python310\lib\unittest\loader.py", line 377, in _get_module_from_name
    __import__(name)
  File "D:\aspose\cells\cloud\sdk-python\test\test_cells_export_object_api.py", line 12, in <module>
    import asposecellscloud
  File "D:\aspose\cells\cloud\sdk-python\asposecellscloud\__init__.py", line 27, in <module>
    from .models.above_average import AboveAverage
  File "D:\aspose\cells\cloud\sdk-python\asposecellscloud\models\__init__.py", line 27, in <module>
    from .above_average import AboveAverage
  File "D:\aspose\cells\cloud\sdk-python\asposecellscloud\models\above_average.py", line 25, in <module>
    from six import iteritems
ModuleNotFoundError: No module named 'six'

]]></error>
	</testcase>
	<testcase classname="unittest.loader._FailedTest" name="test_cells_hypelinks_api" time="0.000">
		<error type="ImportError" message="Failed to import test module: test.test_cells_hypelinks_api
Traceback (most recent call last):
  File &quot;C:\Users\Cells\AppData\Local\Programs\Python\Python310\lib\unittest\loader.py&quot;, line 436, in _find_test_path
    module = self._get_module_from_name(name)
  File &quot;C:\Users\Cells\AppData\Local\Programs\Python\Python310\lib\unittest\loader.py&quot;, line 377, in _get_module_from_name
    __import__(name)
  File &quot;D:\aspose\cells\cloud\sdk-python\test\test_cells_hypelinks_api.py&quot;, line 23, in &lt;module&gt;
    import asposecellscloud
  File &quot;D:\aspose\cells\cloud\sdk-python\asposecellscloud\__init__.py&quot;, line 27, in &lt;module&gt;
    from .models.above_average import AboveAverage
  File &quot;D:\aspose\cells\cloud\sdk-python\asposecellscloud\models\__init__.py&quot;, line 27, in &lt;module&gt;
    from .above_average import AboveAverage
  File &quot;D:\aspose\cells\cloud\sdk-python\asposecellscloud\models\above_average.py&quot;, line 25, in &lt;module&gt;
    from six import iteritems
ModuleNotFoundError: No module named 'six'
"><![CDATA[ImportError: Failed to import test module: test.test_cells_hypelinks_api
Traceback (most recent call last):
  File "C:\Users\Cells\AppData\Local\Programs\Python\Python310\lib\unittest\loader.py", line 436, in _find_test_path
    module = self._get_module_from_name(name)
  File "C:\Users\Cells\AppData\Local\Programs\Python\Python310\lib\unittest\loader.py", line 377, in _get_module_from_name
    __import__(name)
  File "D:\aspose\cells\cloud\sdk-python\test\test_cells_hypelinks_api.py", line 23, in <module>
    import asposecellscloud
  File "D:\aspose\cells\cloud\sdk-python\asposecellscloud\__init__.py", line 27, in <module>
    from .models.above_average import AboveAverage
  File "D:\aspose\cells\cloud\sdk-python\asposecellscloud\models\__init__.py", line 27, in <module>
    from .above_average import AboveAverage
  File "D:\aspose\cells\cloud\sdk-python\asposecellscloud\models\above_average.py", line 25, in <module>
    from six import iteritems
ModuleNotFoundError: No module named 'six'

]]></error>
	</testcase>
	<testcase classname="unittest.loader._FailedTest" name="test_cells_import_api" time="0.000">
		<error type="ImportError" message="Failed to import test module: test.test_cells_import_api
Traceback (most recent call last):
  File &quot;C:\Users\Cells\AppData\Local\Programs\Python\Python310\lib\unittest\loader.py&quot;, line 436, in _find_test_path
    module = self._get_module_from_name(name)
  File &quot;C:\Users\Cells\AppData\Local\Programs\Python\Python310\lib\unittest\loader.py&quot;, line 377, in _get_module_from_name
    __import__(name)
  File &quot;D:\aspose\cells\cloud\sdk-python\test\test_cells_import_api.py&quot;, line 11, in &lt;module&gt;
    from asposecellscloud.models import ImportIntArrayOption
  File &quot;D:\aspose\cells\cloud\sdk-python\asposecellscloud\__init__.py&quot;, line 27, in &lt;module&gt;
    from .models.above_average import AboveAverage
  File &quot;D:\aspose\cells\cloud\sdk-python\asposecellscloud\models\__init__.py&quot;, line 27, in &lt;module&gt;
    from .above_average import AboveAverage
  File &quot;D:\aspose\cells\cloud\sdk-python\asposecellscloud\models\above_average.py&quot;, line 25, in &lt;module&gt;
    from six import iteritems
ModuleNotFoundError: No module named 'six'
"><![CDATA[ImportError: Failed to import test module: test.test_cells_import_api
Traceback (most recent call last):
  File "C:\Users\Cells\AppData\Local\Programs\Python\Python310\lib\unittest\loader.py", line 436, in _find_test_path
    module = self._get_module_from_name(name)
  File "C:\Users\Cells\AppData\Local\Programs\Python\Python310\lib\unittest\loader.py", line 377, in _get_module_from_name
    __import__(name)
  File "D:\aspose\cells\cloud\sdk-python\test\test_cells_import_api.py", line 11, in <module>
    from asposecellscloud.models import ImportIntArrayOption
  File "D:\aspose\cells\cloud\sdk-python\asposecellscloud\__init__.py", line 27, in <module>
    from .models.above_average import AboveAverage
  File "D:\aspose\cells\cloud\sdk-python\asposecellscloud\models\__init__.py", line 27, in <module>
    from .above_average import AboveAverage
  File "D:\aspose\cells\cloud\sdk-python\asposecellscloud\models\above_average.py", line 25, in <module>
    from six import iteritems
ModuleNotFoundError: No module named 'six'

]]></error>
	</testcase>
	<testcase classname="unittest.loader._FailedTest" name="test_cells_list_objects_api" time="0.000">
		<error type="ImportError" message="Failed to import test module: test.test_cells_list_objects_api
Traceback (most recent call last):
  File &quot;C:\Users\Cells\AppData\Local\Programs\Python\Python310\lib\unittest\loader.py&quot;, line 436, in _find_test_path
    module = self._get_module_from_name(name)
  File &quot;C:\Users\Cells\AppData\Local\Programs\Python\Python310\lib\unittest\loader.py&quot;, line 377, in _get_module_from_name
    __import__(name)
  File &quot;D:\aspose\cells\cloud\sdk-python\test\test_cells_list_objects_api.py&quot;, line 23, in &lt;module&gt;
    import asposecellscloud
  File &quot;D:\aspose\cells\cloud\sdk-python\asposecellscloud\__init__.py&quot;, line 27, in &lt;module&gt;
    from .models.above_average import AboveAverage
  File &quot;D:\aspose\cells\cloud\sdk-python\asposecellscloud\models\__init__.py&quot;, line 27, in &lt;module&gt;
    from .above_average import AboveAverage
  File &quot;D:\aspose\cells\cloud\sdk-python\asposecellscloud\models\above_average.py&quot;, line 25, in &lt;module&gt;
    from six import iteritems
ModuleNotFoundError: No module named 'six'
"><![CDATA[ImportError: Failed to import test module: test.test_cells_list_objects_api
Traceback (most recent call last):
  File "C:\Users\Cells\AppData\Local\Programs\Python\Python310\lib\unittest\loader.py", line 436, in _find_test_path
    module = self._get_module_from_name(name)
  File "C:\Users\Cells\AppData\Local\Programs\Python\Python310\lib\unittest\loader.py", line 377, in _get_module_from_name
    __import__(name)
  File "D:\aspose\cells\cloud\sdk-python\test\test_cells_list_objects_api.py", line 23, in <module>
    import asposecellscloud
  File "D:\aspose\cells\cloud\sdk-python\asposecellscloud\__init__.py", line 27, in <module>
    from .models.above_average import AboveAverage
  File "D:\aspose\cells\cloud\sdk-python\asposecellscloud\models\__init__.py", line 27, in <module>
    from .above_average import AboveAverage
  File "D:\aspose\cells\cloud\sdk-python\asposecellscloud\models\above_average.py", line 25, in <module>
    from six import iteritems
ModuleNotFoundError: No module named 'six'

]]></error>
	</testcase>
	<testcase classname="unittest.loader._FailedTest" name="test_cells_merge_api" time="0.000">
		<error type="ImportError" message="Failed to import test module: test.test_cells_merge_api
Traceback (most recent call last):
  File &quot;C:\Users\Cells\AppData\Local\Programs\Python\Python310\lib\unittest\loader.py&quot;, line 436, in _find_test_path
    module = self._get_module_from_name(name)
  File &quot;C:\Users\Cells\AppData\Local\Programs\Python\Python310\lib\unittest\loader.py&quot;, line 377, in _get_module_from_name
    __import__(name)
  File &quot;D:\aspose\cells\cloud\sdk-python\test\test_cells_merge_api.py&quot;, line 12, in &lt;module&gt;
    import asposecellscloud
  File &quot;D:\aspose\cells\cloud\sdk-python\asposecellscloud\__init__.py&quot;, line 27, in &lt;module&gt;
    from .models.above_average import AboveAverage
  File &quot;D:\aspose\cells\cloud\sdk-python\asposecellscloud\models\__init__.py&quot;, line 27, in &lt;module&gt;
    from .above_average import AboveAverage
  File &quot;D:\aspose\cells\cloud\sdk-python\asposecellscloud\models\above_average.py&quot;, line 25, in &lt;module&gt;
    from six import iteritems
ModuleNotFoundError: No module named 'six'
"><![CDATA[ImportError: Failed to import test module: test.test_cells_merge_api
Traceback (most recent call last):
  File "C:\Users\Cells\AppData\Local\Programs\Python\Python310\lib\unittest\loader.py", line 436, in _find_test_path
    module = self._get_module_from_name(name)
  File "C:\Users\Cells\AppData\Local\Programs\Python\Python310\lib\unittest\loader.py", line 377, in _get_module_from_name
    __import__(name)
  File "D:\aspose\cells\cloud\sdk-python\test\test_cells_merge_api.py", line 12, in <module>
    import asposecellscloud
  File "D:\aspose\cells\cloud\sdk-python\asposecellscloud\__init__.py", line 27, in <module>
    from .models.above_average import AboveAverage
  File "D:\aspose\cells\cloud\sdk-python\asposecellscloud\models\__init__.py", line 27, in <module>
    from .above_average import AboveAverage
  File "D:\aspose\cells\cloud\sdk-python\asposecellscloud\models\above_average.py", line 25, in <module>
    from six import iteritems
ModuleNotFoundError: No module named 'six'

]]></error>
	</testcase>
	<testcase classname="unittest.loader._FailedTest" name="test_cells_metadata_api" time="0.000">
		<error type="ImportError" message="Failed to import test module: test.test_cells_metadata_api
Traceback (most recent call last):
  File &quot;C:\Users\Cells\AppData\Local\Programs\Python\Python310\lib\unittest\loader.py&quot;, line 436, in _find_test_path
    module = self._get_module_from_name(name)
  File &quot;C:\Users\Cells\AppData\Local\Programs\Python\Python310\lib\unittest\loader.py&quot;, line 377, in _get_module_from_name
    __import__(name)
  File &quot;D:\aspose\cells\cloud\sdk-python\test\test_cells_metadata_api.py&quot;, line 12, in &lt;module&gt;
    import asposecellscloud
  File &quot;D:\aspose\cells\cloud\sdk-python\asposecellscloud\__init__.py&quot;, line 27, in &lt;module&gt;
    from .models.above_average import AboveAverage
  File &quot;D:\aspose\cells\cloud\sdk-python\asposecellscloud\models\__init__.py&quot;, line 27, in &lt;module&gt;
    from .above_average import AboveAverage
  File &quot;D:\aspose\cells\cloud\sdk-python\asposecellscloud\models\above_average.py&quot;, line 25, in &lt;module&gt;
    from six import iteritems
ModuleNotFoundError: No module named 'six'
"><![CDATA[ImportError: Failed to import test module: test.test_cells_metadata_api
Traceback (most recent call last):
  File "C:\Users\Cells\AppData\Local\Programs\Python\Python310\lib\unittest\loader.py", line 436, in _find_test_path
    module = self._get_module_from_name(name)
  File "C:\Users\Cells\AppData\Local\Programs\Python\Python310\lib\unittest\loader.py", line 377, in _get_module_from_name
    __import__(name)
  File "D:\aspose\cells\cloud\sdk-python\test\test_cells_metadata_api.py", line 12, in <module>
    import asposecellscloud
  File "D:\aspose\cells\cloud\sdk-python\asposecellscloud\__init__.py", line 27, in <module>
    from .models.above_average import AboveAverage
  File "D:\aspose\cells\cloud\sdk-python\asposecellscloud\models\__init__.py", line 27, in <module>
    from .above_average import AboveAverage
  File "D:\aspose\cells\cloud\sdk-python\asposecellscloud\models\above_average.py", line 25, in <module>
    from six import iteritems
ModuleNotFoundError: No module named 'six'

]]></error>
	</testcase>
	<testcase classname="unittest.loader._FailedTest" name="test_cells_ole_objects_api" time="0.000">
		<error type="ImportError" message="Failed to import test module: test.test_cells_ole_objects_api
Traceback (most recent call last):
  File &quot;C:\Users\Cells\AppData\Local\Programs\Python\Python310\lib\unittest\loader.py&quot;, line 436, in _find_test_path
    module = self._get_module_from_name(name)
  File &quot;C:\Users\Cells\AppData\Local\Programs\Python\Python310\lib\unittest\loader.py&quot;, line 377, in _get_module_from_name
    __import__(name)
  File &quot;D:\aspose\cells\cloud\sdk-python\test\test_cells_ole_objects_api.py&quot;, line 23, in &lt;module&gt;
    import asposecellscloud
  File &quot;D:\aspose\cells\cloud\sdk-python\asposecellscloud\__init__.py&quot;, line 27, in &lt;module&gt;
    from .models.above_average import AboveAverage
  File &quot;D:\aspose\cells\cloud\sdk-python\asposecellscloud\models\__init__.py&quot;, line 27, in &lt;module&gt;
    from .above_average import AboveAverage
  File &quot;D:\aspose\cells\cloud\sdk-python\asposecellscloud\models\above_average.py&quot;, line 25, in &lt;module&gt;
    from six import iteritems
ModuleNotFoundError: No module named 'six'
"><![CDATA[ImportError: Failed to import test module: test.test_cells_ole_objects_api
Traceback (most recent call last):
  File "C:\Users\Cells\AppData\Local\Programs\Python\Python310\lib\unittest\loader.py", line 436, in _find_test_path
    module = self._get_module_from_name(name)
  File "C:\Users\Cells\AppData\Local\Programs\Python\Python310\lib\unittest\loader.py", line 377, in _get_module_from_name
    __import__(name)
  File "D:\aspose\cells\cloud\sdk-python\test\test_cells_ole_objects_api.py", line 23, in <module>
    import asposecellscloud
  File "D:\aspose\cells\cloud\sdk-python\asposecellscloud\__init__.py", line 27, in <module>
    from .models.above_average import AboveAverage
  File "D:\aspose\cells\cloud\sdk-python\asposecellscloud\models\__init__.py", line 27, in <module>
    from .above_average import AboveAverage
  File "D:\aspose\cells\cloud\sdk-python\asposecellscloud\models\above_average.py", line 25, in <module>
    from six import iteritems
ModuleNotFoundError: No module named 'six'

]]></error>
	</testcase>
	<testcase classname="unittest.loader._FailedTest" name="test_cells_page_breaks_api" time="0.000">
		<error type="ImportError" message="Failed to import test module: test.test_cells_page_breaks_api
Traceback (most recent call last):
  File &quot;C:\Users\Cells\AppData\Local\Programs\Python\Python310\lib\unittest\loader.py&quot;, line 436, in _find_test_path
    module = self._get_module_from_name(name)
  File &quot;C:\Users\Cells\AppData\Local\Programs\Python\Python310\lib\unittest\loader.py&quot;, line 377, in _get_module_from_name
    __import__(name)
  File &quot;D:\aspose\cells\cloud\sdk-python\test\test_cells_page_breaks_api.py&quot;, line 23, in &lt;module&gt;
    import asposecellscloud
  File &quot;D:\aspose\cells\cloud\sdk-python\asposecellscloud\__init__.py&quot;, line 27, in &lt;module&gt;
    from .models.above_average import AboveAverage
  File &quot;D:\aspose\cells\cloud\sdk-python\asposecellscloud\models\__init__.py&quot;, line 27, in &lt;module&gt;
    from .above_average import AboveAverage
  File &quot;D:\aspose\cells\cloud\sdk-python\asposecellscloud\models\above_average.py&quot;, line 25, in &lt;module&gt;
    from six import iteritems
ModuleNotFoundError: No module named 'six'
"><![CDATA[ImportError: Failed to import test module: test.test_cells_page_breaks_api
Traceback (most recent call last):
  File "C:\Users\Cells\AppData\Local\Programs\Python\Python310\lib\unittest\loader.py", line 436, in _find_test_path
    module = self._get_module_from_name(name)
  File "C:\Users\Cells\AppData\Local\Programs\Python\Python310\lib\unittest\loader.py", line 377, in _get_module_from_name
    __import__(name)
  File "D:\aspose\cells\cloud\sdk-python\test\test_cells_page_breaks_api.py", line 23, in <module>
    import asposecellscloud
  File "D:\aspose\cells\cloud\sdk-python\asposecellscloud\__init__.py", line 27, in <module>
    from .models.above_average import AboveAverage
  File "D:\aspose\cells\cloud\sdk-python\asposecellscloud\models\__init__.py", line 27, in <module>
    from .above_average import AboveAverage
  File "D:\aspose\cells\cloud\sdk-python\asposecellscloud\models\above_average.py", line 25, in <module>
    from six import iteritems
ModuleNotFoundError: No module named 'six'

]]></error>
	</testcase>
	<testcase classname="unittest.loader._FailedTest" name="test_cells_page_setup_api" time="0.000">
		<error type="ImportError" message="Failed to import test module: test.test_cells_page_setup_api
Traceback (most recent call last):
  File &quot;C:\Users\Cells\AppData\Local\Programs\Python\Python310\lib\unittest\loader.py&quot;, line 436, in _find_test_path
    module = self._get_module_from_name(name)
  File &quot;C:\Users\Cells\AppData\Local\Programs\Python\Python310\lib\unittest\loader.py&quot;, line 377, in _get_module_from_name
    __import__(name)
  File &quot;D:\aspose\cells\cloud\sdk-python\test\test_cells_page_setup_api.py&quot;, line 23, in &lt;module&gt;
    import asposecellscloud
  File &quot;D:\aspose\cells\cloud\sdk-python\asposecellscloud\__init__.py&quot;, line 27, in &lt;module&gt;
    from .models.above_average import AboveAverage
  File &quot;D:\aspose\cells\cloud\sdk-python\asposecellscloud\models\__init__.py&quot;, line 27, in &lt;module&gt;
    from .above_average import AboveAverage
  File &quot;D:\aspose\cells\cloud\sdk-python\asposecellscloud\models\above_average.py&quot;, line 25, in &lt;module&gt;
    from six import iteritems
ModuleNotFoundError: No module named 'six'
"><![CDATA[ImportError: Failed to import test module: test.test_cells_page_setup_api
Traceback (most recent call last):
  File "C:\Users\Cells\AppData\Local\Programs\Python\Python310\lib\unittest\loader.py", line 436, in _find_test_path
    module = self._get_module_from_name(name)
  File "C:\Users\Cells\AppData\Local\Programs\Python\Python310\lib\unittest\loader.py", line 377, in _get_module_from_name
    __import__(name)
  File "D:\aspose\cells\cloud\sdk-python\test\test_cells_page_setup_api.py", line 23, in <module>
    import asposecellscloud
  File "D:\aspose\cells\cloud\sdk-python\asposecellscloud\__init__.py", line 27, in <module>
    from .models.above_average import AboveAverage
  File "D:\aspose\cells\cloud\sdk-python\asposecellscloud\models\__init__.py", line 27, in <module>
    from .above_average import AboveAverage
  File "D:\aspose\cells\cloud\sdk-python\asposecellscloud\models\above_average.py", line 25, in <module>
    from six import iteritems
ModuleNotFoundError: No module named 'six'

]]></error>
	</testcase>
	<testcase classname="unittest.loader._FailedTest" name="test_cells_pictures_api" time="0.000">
		<error type="ImportError" message="Failed to import test module: test.test_cells_pictures_api
Traceback (most recent call last):
  File &quot;C:\Users\Cells\AppData\Local\Programs\Python\Python310\lib\unittest\loader.py&quot;, line 436, in _find_test_path
    module = self._get_module_from_name(name)
  File &quot;C:\Users\Cells\AppData\Local\Programs\Python\Python310\lib\unittest\loader.py&quot;, line 377, in _get_module_from_name
    __import__(name)
  File &quot;D:\aspose\cells\cloud\sdk-python\test\test_cells_pictures_api.py&quot;, line 23, in &lt;module&gt;
    import asposecellscloud
  File &quot;D:\aspose\cells\cloud\sdk-python\asposecellscloud\__init__.py&quot;, line 27, in &lt;module&gt;
    from .models.above_average import AboveAverage
  File &quot;D:\aspose\cells\cloud\sdk-python\asposecellscloud\models\__init__.py&quot;, line 27, in &lt;module&gt;
    from .above_average import AboveAverage
  File &quot;D:\aspose\cells\cloud\sdk-python\asposecellscloud\models\above_average.py&quot;, line 25, in &lt;module&gt;
    from six import iteritems
ModuleNotFoundError: No module named 'six'
"><![CDATA[ImportError: Failed to import test module: test.test_cells_pictures_api
Traceback (most recent call last):
  File "C:\Users\Cells\AppData\Local\Programs\Python\Python310\lib\unittest\loader.py", line 436, in _find_test_path
    module = self._get_module_from_name(name)
  File "C:\Users\Cells\AppData\Local\Programs\Python\Python310\lib\unittest\loader.py", line 377, in _get_module_from_name
    __import__(name)
  File "D:\aspose\cells\cloud\sdk-python\test\test_cells_pictures_api.py", line 23, in <module>
    import asposecellscloud
  File "D:\aspose\cells\cloud\sdk-python\asposecellscloud\__init__.py", line 27, in <module>
    from .models.above_average import AboveAverage
  File "D:\aspose\cells\cloud\sdk-python\asposecellscloud\models\__init__.py", line 27, in <module>
    from .above_average import AboveAverage
  File "D:\aspose\cells\cloud\sdk-python\asposecellscloud\models\above_average.py", line 25, in <module>
    from six import iteritems
ModuleNotFoundError: No module named 'six'

]]></error>
	</testcase>
	<testcase classname="unittest.loader._FailedTest" name="test_cells_pivot_tables_api" time="0.000">
		<error type="ImportError" message="Failed to import test module: test.test_cells_pivot_tables_api
Traceback (most recent call last):
  File &quot;C:\Users\Cells\AppData\Local\Programs\Python\Python310\lib\unittest\loader.py&quot;, line 436, in _find_test_path
    module = self._get_module_from_name(name)
  File &quot;C:\Users\Cells\AppData\Local\Programs\Python\Python310\lib\unittest\loader.py&quot;, line 377, in _get_module_from_name
    __import__(name)
  File &quot;D:\aspose\cells\cloud\sdk-python\test\test_cells_pivot_tables_api.py&quot;, line 23, in &lt;module&gt;
    import asposecellscloud
  File &quot;D:\aspose\cells\cloud\sdk-python\asposecellscloud\__init__.py&quot;, line 27, in &lt;module&gt;
    from .models.above_average import AboveAverage
  File &quot;D:\aspose\cells\cloud\sdk-python\asposecellscloud\models\__init__.py&quot;, line 27, in &lt;module&gt;
    from .above_average import AboveAverage
  File &quot;D:\aspose\cells\cloud\sdk-python\asposecellscloud\models\above_average.py&quot;, line 25, in &lt;module&gt;
    from six import iteritems
ModuleNotFoundError: No module named 'six'
"><![CDATA[ImportError: Failed to import test module: test.test_cells_pivot_tables_api
Traceback (most recent call last):
  File "C:\Users\Cells\AppData\Local\Programs\Python\Python310\lib\unittest\loader.py", line 436, in _find_test_path
    module = self._get_module_from_name(name)
  File "C:\Users\Cells\AppData\Local\Programs\Python\Python310\lib\unittest\loader.py", line 377, in _get_module_from_name
    __import__(name)
  File "D:\aspose\cells\cloud\sdk-python\test\test_cells_pivot_tables_api.py", line 23, in <module>
    import asposecellscloud
  File "D:\aspose\cells\cloud\sdk-python\asposecellscloud\__init__.py", line 27, in <module>
    from .models.above_average import AboveAverage
  File "D:\aspose\cells\cloud\sdk-python\asposecellscloud\models\__init__.py", line 27, in <module>
    from .above_average import AboveAverage
  File "D:\aspose\cells\cloud\sdk-python\asposecellscloud\models\above_average.py", line 25, in <module>
    from six import iteritems
ModuleNotFoundError: No module named 'six'

]]></error>
	</testcase>
	<testcase classname="unittest.loader._FailedTest" name="test_cells_properties_api" time="0.000">
		<error type="ImportError" message="Failed to import test module: test.test_cells_properties_api
Traceback (most recent call last):
  File &quot;C:\Users\Cells\AppData\Local\Programs\Python\Python310\lib\unittest\loader.py&quot;, line 436, in _find_test_path
    module = self._get_module_from_name(name)
  File &quot;C:\Users\Cells\AppData\Local\Programs\Python\Python310\lib\unittest\loader.py&quot;, line 377, in _get_module_from_name
    __import__(name)
  File &quot;D:\aspose\cells\cloud\sdk-python\test\test_cells_properties_api.py&quot;, line 23, in &lt;module&gt;
    import asposecellscloud
  File &quot;D:\aspose\cells\cloud\sdk-python\asposecellscloud\__init__.py&quot;, line 27, in &lt;module&gt;
    from .models.above_average import AboveAverage
  File &quot;D:\aspose\cells\cloud\sdk-python\asposecellscloud\models\__init__.py&quot;, line 27, in &lt;module&gt;
    from .above_average import AboveAverage
  File &quot;D:\aspose\cells\cloud\sdk-python\asposecellscloud\models\above_average.py&quot;, line 25, in &lt;module&gt;
    from six import iteritems
ModuleNotFoundError: No module named 'six'
"><![CDATA[ImportError: Failed to import test module: test.test_cells_properties_api
Traceback (most recent call last):
  File "C:\Users\Cells\AppData\Local\Programs\Python\Python310\lib\unittest\loader.py", line 436, in _find_test_path
    module = self._get_module_from_name(name)
  File "C:\Users\Cells\AppData\Local\Programs\Python\Python310\lib\unittest\loader.py", line 377, in _get_module_from_name
    __import__(name)
  File "D:\aspose\cells\cloud\sdk-python\test\test_cells_properties_api.py", line 23, in <module>
    import asposecellscloud
  File "D:\aspose\cells\cloud\sdk-python\asposecellscloud\__init__.py", line 27, in <module>
    from .models.above_average import AboveAverage
  File "D:\aspose\cells\cloud\sdk-python\asposecellscloud\models\__init__.py", line 27, in <module>
    from .above_average import AboveAverage
  File "D:\aspose\cells\cloud\sdk-python\asposecellscloud\models\above_average.py", line 25, in <module>
    from six import iteritems
ModuleNotFoundError: No module named 'six'

]]></error>
	</testcase>
	<testcase classname="unittest.loader._FailedTest" name="test_cells_protect_api" time="0.000">
		<error type="ImportError" message="Failed to import test module: test.test_cells_protect_api
Traceback (most recent call last):
  File &quot;C:\Users\Cells\AppData\Local\Programs\Python\Python310\lib\unittest\loader.py&quot;, line 436, in _find_test_path
    module = self._get_module_from_name(name)
  File &quot;C:\Users\Cells\AppData\Local\Programs\Python\Python310\lib\unittest\loader.py&quot;, line 377, in _get_module_from_name
    __import__(name)
  File &quot;D:\aspose\cells\cloud\sdk-python\test\test_cells_protect_api.py&quot;, line 12, in &lt;module&gt;
    import asposecellscloud
  File &quot;D:\aspose\cells\cloud\sdk-python\asposecellscloud\__init__.py&quot;, line 27, in &lt;module&gt;
    from .models.above_average import AboveAverage
  File &quot;D:\aspose\cells\cloud\sdk-python\asposecellscloud\models\__init__.py&quot;, line 27, in &lt;module&gt;
    from .above_average import AboveAverage
  File &quot;D:\aspose\cells\cloud\sdk-python\asposecellscloud\models\above_average.py&quot;, line 25, in &lt;module&gt;
    from six import iteritems
ModuleNotFoundError: No module named 'six'
"><![CDATA[ImportError: Failed to import test module: test.test_cells_protect_api
Traceback (most recent call last):
  File "C:\Users\Cells\AppData\Local\Programs\Python\Python310\lib\unittest\loader.py", line 436, in _find_test_path
    module = self._get_module_from_name(name)
  File "C:\Users\Cells\AppData\Local\Programs\Python\Python310\lib\unittest\loader.py", line 377, in _get_module_from_name
    __import__(name)
  File "D:\aspose\cells\cloud\sdk-python\test\test_cells_protect_api.py", line 12, in <module>
    import asposecellscloud
  File "D:\aspose\cells\cloud\sdk-python\asposecellscloud\__init__.py", line 27, in <module>
    from .models.above_average import AboveAverage
  File "D:\aspose\cells\cloud\sdk-python\asposecellscloud\models\__init__.py", line 27, in <module>
    from .above_average import AboveAverage
  File "D:\aspose\cells\cloud\sdk-python\asposecellscloud\models\above_average.py", line 25, in <module>
    from six import iteritems
ModuleNotFoundError: No module named 'six'

]]></error>
	</testcase>
	<testcase classname="unittest.loader._FailedTest" name="test_cells_ranges_api" time="0.000">
		<error type="ImportError" message="Failed to import test module: test.test_cells_ranges_api
Traceback (most recent call last):
  File &quot;C:\Users\Cells\AppData\Local\Programs\Python\Python310\lib\unittest\loader.py&quot;, line 436, in _find_test_path
    module = self._get_module_from_name(name)
  File &quot;C:\Users\Cells\AppData\Local\Programs\Python\Python310\lib\unittest\loader.py&quot;, line 377, in _get_module_from_name
    __import__(name)
  File &quot;D:\aspose\cells\cloud\sdk-python\test\test_cells_ranges_api.py&quot;, line 23, in &lt;module&gt;
    import asposecellscloud
  File &quot;D:\aspose\cells\cloud\sdk-python\asposecellscloud\__init__.py&quot;, line 27, in &lt;module&gt;
    from .models.above_average import AboveAverage
  File &quot;D:\aspose\cells\cloud\sdk-python\asposecellscloud\models\__init__.py&quot;, line 27, in &lt;module&gt;
    from .above_average import AboveAverage
  File &quot;D:\aspose\cells\cloud\sdk-python\asposecellscloud\models\above_average.py&quot;, line 25, in &lt;module&gt;
    from six import iteritems
ModuleNotFoundError: No module named 'six'
"><![CDATA[ImportError: Failed to import test module: test.test_cells_ranges_api
Traceback (most recent call last):
  File "C:\Users\Cells\AppData\Local\Programs\Python\Python310\lib\unittest\loader.py", line 436, in _find_test_path
    module = self._get_module_from_name(name)
  File "C:\Users\Cells\AppData\Local\Programs\Python\Python310\lib\unittest\loader.py", line 377, in _get_module_from_name
    __import__(name)
  File "D:\aspose\cells\cloud\sdk-python\test\test_cells_ranges_api.py", line 23, in <module>
    import asposecellscloud
  File "D:\aspose\cells\cloud\sdk-python\asposecellscloud\__init__.py", line 27, in <module>
    from .models.above_average import AboveAverage
  File "D:\aspose\cells\cloud\sdk-python\asposecellscloud\models\__init__.py", line 27, in <module>
    from .above_average import AboveAverage
  File "D:\aspose\cells\cloud\sdk-python\asposecellscloud\models\above_average.py", line 25, in <module>
    from six import iteritems
ModuleNotFoundError: No module named 'six'

]]></error>
	</testcase>
	<testcase classname="unittest.loader._FailedTest" name="test_cells_replace_api" time="0.000">
		<error type="ImportError" message="Failed to import test module: test.test_cells_replace_api
Traceback (most recent call last):
  File &quot;C:\Users\Cells\AppData\Local\Programs\Python\Python310\lib\unittest\loader.py&quot;, line 436, in _find_test_path
    module = self._get_module_from_name(name)
  File &quot;C:\Users\Cells\AppData\Local\Programs\Python\Python310\lib\unittest\loader.py&quot;, line 377, in _get_module_from_name
    __import__(name)
  File &quot;D:\aspose\cells\cloud\sdk-python\test\test_cells_replace_api.py&quot;, line 12, in &lt;module&gt;
    import asposecellscloud
  File &quot;D:\aspose\cells\cloud\sdk-python\asposecellscloud\__init__.py&quot;, line 27, in &lt;module&gt;
    from .models.above_average import AboveAverage
  File &quot;D:\aspose\cells\cloud\sdk-python\asposecellscloud\models\__init__.py&quot;, line 27, in &lt;module&gt;
    from .above_average import AboveAverage
  File &quot;D:\aspose\cells\cloud\sdk-python\asposecellscloud\models\above_average.py&quot;, line 25, in &lt;module&gt;
    from six import iteritems
ModuleNotFoundError: No module named 'six'
"><![CDATA[ImportError: Failed to import test module: test.test_cells_replace_api
Traceback (most recent call last):
  File "C:\Users\Cells\AppData\Local\Programs\Python\Python310\lib\unittest\loader.py", line 436, in _find_test_path
    module = self._get_module_from_name(name)
  File "C:\Users\Cells\AppData\Local\Programs\Python\Python310\lib\unittest\loader.py", line 377, in _get_module_from_name
    __import__(name)
  File "D:\aspose\cells\cloud\sdk-python\test\test_cells_replace_api.py", line 12, in <module>
    import asposecellscloud
  File "D:\aspose\cells\cloud\sdk-python\asposecellscloud\__init__.py", line 27, in <module>
    from .models.above_average import AboveAverage
  File "D:\aspose\cells\cloud\sdk-python\asposecellscloud\models\__init__.py", line 27, in <module>
    from .above_average import AboveAverage
  File "D:\aspose\cells\cloud\sdk-python\asposecellscloud\models\above_average.py", line 25, in <module>
    from six import iteritems
ModuleNotFoundError: No module named 'six'

]]></error>
	</testcase>
	<testcase classname="unittest.loader._FailedTest" name="test_cells_reverse_api" time="0.000">
		<error type="ImportError" message="Failed to import test module: test.test_cells_reverse_api
Traceback (most recent call last):
  File &quot;C:\Users\Cells\AppData\Local\Programs\Python\Python310\lib\unittest\loader.py&quot;, line 436, in _find_test_path
    module = self._get_module_from_name(name)
  File &quot;C:\Users\Cells\AppData\Local\Programs\Python\Python310\lib\unittest\loader.py&quot;, line 377, in _get_module_from_name
    __import__(name)
  File &quot;D:\aspose\cells\cloud\sdk-python\test\test_cells_reverse_api.py&quot;, line 12, in &lt;module&gt;
    import asposecellscloud
  File &quot;D:\aspose\cells\cloud\sdk-python\asposecellscloud\__init__.py&quot;, line 27, in &lt;module&gt;
    from .models.above_average import AboveAverage
  File &quot;D:\aspose\cells\cloud\sdk-python\asposecellscloud\models\__init__.py&quot;, line 27, in &lt;module&gt;
    from .above_average import AboveAverage
  File &quot;D:\aspose\cells\cloud\sdk-python\asposecellscloud\models\above_average.py&quot;, line 25, in &lt;module&gt;
    from six import iteritems
ModuleNotFoundError: No module named 'six'
"><![CDATA[ImportError: Failed to import test module: test.test_cells_reverse_api
Traceback (most recent call last):
  File "C:\Users\Cells\AppData\Local\Programs\Python\Python310\lib\unittest\loader.py", line 436, in _find_test_path
    module = self._get_module_from_name(name)
  File "C:\Users\Cells\AppData\Local\Programs\Python\Python310\lib\unittest\loader.py", line 377, in _get_module_from_name
    __import__(name)
  File "D:\aspose\cells\cloud\sdk-python\test\test_cells_reverse_api.py", line 12, in <module>
    import asposecellscloud
  File "D:\aspose\cells\cloud\sdk-python\asposecellscloud\__init__.py", line 27, in <module>
    from .models.above_average import AboveAverage
  File "D:\aspose\cells\cloud\sdk-python\asposecellscloud\models\__init__.py", line 27, in <module>
    from .above_average import AboveAverage
  File "D:\aspose\cells\cloud\sdk-python\asposecellscloud\models\above_average.py", line 25, in <module>
    from six import iteritems
ModuleNotFoundError: No module named 'six'

]]></error>
	</testcase>
	<testcase classname="unittest.loader._FailedTest" name="test_cells_save_as_api" time="0.000">
		<error type="ImportError" message="Failed to import test module: test.test_cells_save_as_api
Traceback (most recent call last):
  File &quot;C:\Users\Cells\AppData\Local\Programs\Python\Python310\lib\unittest\loader.py&quot;, line 436, in _find_test_path
    module = self._get_module_from_name(name)
  File &quot;C:\Users\Cells\AppData\Local\Programs\Python\Python310\lib\unittest\loader.py&quot;, line 377, in _get_module_from_name
    __import__(name)
  File &quot;D:\aspose\cells\cloud\sdk-python\test\test_cells_save_as_api.py&quot;, line 23, in &lt;module&gt;
    import asposecellscloud
  File &quot;D:\aspose\cells\cloud\sdk-python\asposecellscloud\__init__.py&quot;, line 27, in &lt;module&gt;
    from .models.above_average import AboveAverage
  File &quot;D:\aspose\cells\cloud\sdk-python\asposecellscloud\models\__init__.py&quot;, line 27, in &lt;module&gt;
    from .above_average import AboveAverage
  File &quot;D:\aspose\cells\cloud\sdk-python\asposecellscloud\models\above_average.py&quot;, line 25, in &lt;module&gt;
    from six import iteritems
ModuleNotFoundError: No module named 'six'
"><![CDATA[ImportError: Failed to import test module: test.test_cells_save_as_api
Traceback (most recent call last):
  File "C:\Users\Cells\AppData\Local\Programs\Python\Python310\lib\unittest\loader.py", line 436, in _find_test_path
    module = self._get_module_from_name(name)
  File "C:\Users\Cells\AppData\Local\Programs\Python\Python310\lib\unittest\loader.py", line 377, in _get_module_from_name
    __import__(name)
  File "D:\aspose\cells\cloud\sdk-python\test\test_cells_save_as_api.py", line 23, in <module>
    import asposecellscloud
  File "D:\aspose\cells\cloud\sdk-python\asposecellscloud\__init__.py", line 27, in <module>
    from .models.above_average import AboveAverage
  File "D:\aspose\cells\cloud\sdk-python\asposecellscloud\models\__init__.py", line 27, in <module>
    from .above_average import AboveAverage
  File "D:\aspose\cells\cloud\sdk-python\asposecellscloud\models\above_average.py", line 25, in <module>
    from six import iteritems
ModuleNotFoundError: No module named 'six'

]]></error>
	</testcase>
	<testcase classname="unittest.loader._FailedTest" name="test_cells_search_api" time="0.000">
		<error type="ImportError" message="Failed to import test module: test.test_cells_search_api
Traceback (most recent call last):
  File &quot;C:\Users\Cells\AppData\Local\Programs\Python\Python310\lib\unittest\loader.py&quot;, line 436, in _find_test_path
    module = self._get_module_from_name(name)
  File &quot;C:\Users\Cells\AppData\Local\Programs\Python\Python310\lib\unittest\loader.py&quot;, line 377, in _get_module_from_name
    __import__(name)
  File &quot;D:\aspose\cells\cloud\sdk-python\test\test_cells_search_api.py&quot;, line 12, in &lt;module&gt;
    import asposecellscloud
  File &quot;D:\aspose\cells\cloud\sdk-python\asposecellscloud\__init__.py&quot;, line 27, in &lt;module&gt;
    from .models.above_average import AboveAverage
  File &quot;D:\aspose\cells\cloud\sdk-python\asposecellscloud\models\__init__.py&quot;, line 27, in &lt;module&gt;
    from .above_average import AboveAverage
  File &quot;D:\aspose\cells\cloud\sdk-python\asposecellscloud\models\above_average.py&quot;, line 25, in &lt;module&gt;
    from six import iteritems
ModuleNotFoundError: No module named 'six'
"><![CDATA[ImportError: Failed to import test module: test.test_cells_search_api
Traceback (most recent call last):
  File "C:\Users\Cells\AppData\Local\Programs\Python\Python310\lib\unittest\loader.py", line 436, in _find_test_path
    module = self._get_module_from_name(name)
  File "C:\Users\Cells\AppData\Local\Programs\Python\Python310\lib\unittest\loader.py", line 377, in _get_module_from_name
    __import__(name)
  File "D:\aspose\cells\cloud\sdk-python\test\test_cells_search_api.py", line 12, in <module>
    import asposecellscloud
  File "D:\aspose\cells\cloud\sdk-python\asposecellscloud\__init__.py", line 27, in <module>
    from .models.above_average import AboveAverage
  File "D:\aspose\cells\cloud\sdk-python\asposecellscloud\models\__init__.py", line 27, in <module>
    from .above_average import AboveAverage
  File "D:\aspose\cells\cloud\sdk-python\asposecellscloud\models\above_average.py", line 25, in <module>
    from six import iteritems
ModuleNotFoundError: No module named 'six'

]]></error>
	</testcase>
	<testcase classname="unittest.loader._FailedTest" name="test_cells_shapes_api" time="0.001">
		<error type="ImportError" message="Failed to import test module: test.test_cells_shapes_api
Traceback (most recent call last):
  File &quot;C:\Users\Cells\AppData\Local\Programs\Python\Python310\lib\unittest\loader.py&quot;, line 436, in _find_test_path
    module = self._get_module_from_name(name)
  File &quot;C:\Users\Cells\AppData\Local\Programs\Python\Python310\lib\unittest\loader.py&quot;, line 377, in _get_module_from_name
    __import__(name)
  File &quot;D:\aspose\cells\cloud\sdk-python\test\test_cells_shapes_api.py&quot;, line 23, in &lt;module&gt;
    import asposecellscloud
  File &quot;D:\aspose\cells\cloud\sdk-python\asposecellscloud\__init__.py&quot;, line 27, in &lt;module&gt;
    from .models.above_average import AboveAverage
  File &quot;D:\aspose\cells\cloud\sdk-python\asposecellscloud\models\__init__.py&quot;, line 27, in &lt;module&gt;
    from .above_average import AboveAverage
  File &quot;D:\aspose\cells\cloud\sdk-python\asposecellscloud\models\above_average.py&quot;, line 25, in &lt;module&gt;
    from six import iteritems
ModuleNotFoundError: No module named 'six'
"><![CDATA[ImportError: Failed to import test module: test.test_cells_shapes_api
Traceback (most recent call last):
  File "C:\Users\Cells\AppData\Local\Programs\Python\Python310\lib\unittest\loader.py", line 436, in _find_test_path
    module = self._get_module_from_name(name)
  File "C:\Users\Cells\AppData\Local\Programs\Python\Python310\lib\unittest\loader.py", line 377, in _get_module_from_name
    __import__(name)
  File "D:\aspose\cells\cloud\sdk-python\test\test_cells_shapes_api.py", line 23, in <module>
    import asposecellscloud
  File "D:\aspose\cells\cloud\sdk-python\asposecellscloud\__init__.py", line 27, in <module>
    from .models.above_average import AboveAverage
  File "D:\aspose\cells\cloud\sdk-python\asposecellscloud\models\__init__.py", line 27, in <module>
    from .above_average import AboveAverage
  File "D:\aspose\cells\cloud\sdk-python\asposecellscloud\models\above_average.py", line 25, in <module>
    from six import iteritems
ModuleNotFoundError: No module named 'six'

]]></error>
	</testcase>
	<testcase classname="unittest.loader._FailedTest" name="test_cells_sparklinegroups_api" time="0.000">
		<error type="ImportError" message="Failed to import test module: test.test_cells_sparklinegroups_api
Traceback (most recent call last):
  File &quot;C:\Users\Cells\AppData\Local\Programs\Python\Python310\lib\unittest\loader.py&quot;, line 436, in _find_test_path
    module = self._get_module_from_name(name)
  File &quot;C:\Users\Cells\AppData\Local\Programs\Python\Python310\lib\unittest\loader.py&quot;, line 377, in _get_module_from_name
    __import__(name)
  File &quot;D:\aspose\cells\cloud\sdk-python\test\test_cells_sparklinegroups_api.py&quot;, line 12, in &lt;module&gt;
    import asposecellscloud
  File &quot;D:\aspose\cells\cloud\sdk-python\asposecellscloud\__init__.py&quot;, line 27, in &lt;module&gt;
    from .models.above_average import AboveAverage
  File &quot;D:\aspose\cells\cloud\sdk-python\asposecellscloud\models\__init__.py&quot;, line 27, in &lt;module&gt;
    from .above_average import AboveAverage
  File &quot;D:\aspose\cells\cloud\sdk-python\asposecellscloud\models\above_average.py&quot;, line 25, in &lt;module&gt;
    from six import iteritems
ModuleNotFoundError: No module named 'six'
"><![CDATA[ImportError: Failed to import test module: test.test_cells_sparklinegroups_api
Traceback (most recent call last):
  File "C:\Users\Cells\AppData\Local\Programs\Python\Python310\lib\unittest\loader.py", line 436, in _find_test_path
    module = self._get_module_from_name(name)
  File "C:\Users\Cells\AppData\Local\Programs\Python\Python310\lib\unittest\loader.py", line 377, in _get_module_from_name
    __import__(name)
  File "D:\aspose\cells\cloud\sdk-python\test\test_cells_sparklinegroups_api.py", line 12, in <module>
    import asposecellscloud
  File "D:\aspose\cells\cloud\sdk-python\asposecellscloud\__init__.py", line 27, in <module>
    from .models.above_average import AboveAverage
  File "D:\aspose\cells\cloud\sdk-python\asposecellscloud\models\__init__.py", line 27, in <module>
    from .above_average import AboveAverage
  File "D:\aspose\cells\cloud\sdk-python\asposecellscloud\models\above_average.py", line 25, in <module>
    from six import iteritems
ModuleNotFoundError: No module named 'six'

]]></error>
	</testcase>
	<testcase classname="unittest.loader._FailedTest" name="test_cells_split_api" time="0.000">
		<error type="ImportError" message="Failed to import test module: test.test_cells_split_api
Traceback (most recent call last):
  File &quot;C:\Users\Cells\AppData\Local\Programs\Python\Python310\lib\unittest\loader.py&quot;, line 436, in _find_test_path
    module = self._get_module_from_name(name)
  File &quot;C:\Users\Cells\AppData\Local\Programs\Python\Python310\lib\unittest\loader.py&quot;, line 377, in _get_module_from_name
    __import__(name)
  File &quot;D:\aspose\cells\cloud\sdk-python\test\test_cells_split_api.py&quot;, line 12, in &lt;module&gt;
    import asposecellscloud
  File &quot;D:\aspose\cells\cloud\sdk-python\asposecellscloud\__init__.py&quot;, line 27, in &lt;module&gt;
    from .models.above_average import AboveAverage
  File &quot;D:\aspose\cells\cloud\sdk-python\asposecellscloud\models\__init__.py&quot;, line 27, in &lt;module&gt;
    from .above_average import AboveAverage
  File &quot;D:\aspose\cells\cloud\sdk-python\asposecellscloud\models\above_average.py&quot;, line 25, in &lt;module&gt;
    from six import iteritems
ModuleNotFoundError: No module named 'six'
"><![CDATA[ImportError: Failed to import test module: test.test_cells_split_api
Traceback (most recent call last):
  File "C:\Users\Cells\AppData\Local\Programs\Python\Python310\lib\unittest\loader.py", line 436, in _find_test_path
    module = self._get_module_from_name(name)
  File "C:\Users\Cells\AppData\Local\Programs\Python\Python310\lib\unittest\loader.py", line 377, in _get_module_from_name
    __import__(name)
  File "D:\aspose\cells\cloud\sdk-python\test\test_cells_split_api.py", line 12, in <module>
    import asposecellscloud
  File "D:\aspose\cells\cloud\sdk-python\asposecellscloud\__init__.py", line 27, in <module>
    from .models.above_average import AboveAverage
  File "D:\aspose\cells\cloud\sdk-python\asposecellscloud\models\__init__.py", line 27, in <module>
    from .above_average import AboveAverage
  File "D:\aspose\cells\cloud\sdk-python\asposecellscloud\models\above_average.py", line 25, in <module>
    from six import iteritems
ModuleNotFoundError: No module named 'six'

]]></error>
	</testcase>
	<testcase classname="unittest.loader._FailedTest" name="test_cells_task_api" time="0.000">
		<error type="ImportError" message="Failed to import test module: test.test_cells_task_api
Traceback (most recent call last):
  File &quot;C:\Users\Cells\AppData\Local\Programs\Python\Python310\lib\unittest\loader.py&quot;, line 436, in _find_test_path
    module = self._get_module_from_name(name)
  File &quot;C:\Users\Cells\AppData\Local\Programs\Python\Python310\lib\unittest\loader.py&quot;, line 377, in _get_module_from_name
    __import__(name)
  File &quot;D:\aspose\cells\cloud\sdk-python\test\test_cells_task_api.py&quot;, line 23, in &lt;module&gt;
    import asposecellscloud
  File &quot;D:\aspose\cells\cloud\sdk-python\asposecellscloud\__init__.py&quot;, line 27, in &lt;module&gt;
    from .models.above_average import AboveAverage
  File &quot;D:\aspose\cells\cloud\sdk-python\asposecellscloud\models\__init__.py&quot;, line 27, in &lt;module&gt;
    from .above_average import AboveAverage
  File &quot;D:\aspose\cells\cloud\sdk-python\asposecellscloud\models\above_average.py&quot;, line 25, in &lt;module&gt;
    from six import iteritems
ModuleNotFoundError: No module named 'six'
"><![CDATA[ImportError: Failed to import test module: test.test_cells_task_api
Traceback (most recent call last):
  File "C:\Users\Cells\AppData\Local\Programs\Python\Python310\lib\unittest\loader.py", line 436, in _find_test_path
    module = self._get_module_from_name(name)
  File "C:\Users\Cells\AppData\Local\Programs\Python\Python310\lib\unittest\loader.py", line 377, in _get_module_from_name
    __import__(name)
  File "D:\aspose\cells\cloud\sdk-python\test\test_cells_task_api.py", line 23, in <module>
    import asposecellscloud
  File "D:\aspose\cells\cloud\sdk-python\asposecellscloud\__init__.py", line 27, in <module>
    from .models.above_average import AboveAverage
  File "D:\aspose\cells\cloud\sdk-python\asposecellscloud\models\__init__.py", line 27, in <module>
    from .above_average import AboveAverage
  File "D:\aspose\cells\cloud\sdk-python\asposecellscloud\models\above_average.py", line 25, in <module>
    from six import iteritems
ModuleNotFoundError: No module named 'six'

]]></error>
	</testcase>
	<testcase classname="unittest.loader._FailedTest" name="test_cells_unlock_api" time="0.000">
		<error type="ImportError" message="Failed to import test module: test.test_cells_unlock_api
Traceback (most recent call last):
  File &quot;C:\Users\Cells\AppData\Local\Programs\Python\Python310\lib\unittest\loader.py&quot;, line 436, in _find_test_path
    module = self._get_module_from_name(name)
  File &quot;C:\Users\Cells\AppData\Local\Programs\Python\Python310\lib\unittest\loader.py&quot;, line 377, in _get_module_from_name
    __import__(name)
  File &quot;D:\aspose\cells\cloud\sdk-python\test\test_cells_unlock_api.py&quot;, line 12, in &lt;module&gt;
    import asposecellscloud
  File &quot;D:\aspose\cells\cloud\sdk-python\asposecellscloud\__init__.py&quot;, line 27, in &lt;module&gt;
    from .models.above_average import AboveAverage
  File &quot;D:\aspose\cells\cloud\sdk-python\asposecellscloud\models\__init__.py&quot;, line 27, in &lt;module&gt;
    from .above_average import AboveAverage
  File &quot;D:\aspose\cells\cloud\sdk-python\asposecellscloud\models\above_average.py&quot;, line 25, in &lt;module&gt;
    from six import iteritems
ModuleNotFoundError: No module named 'six'
"><![CDATA[ImportError: Failed to import test module: test.test_cells_unlock_api
Traceback (most recent call last):
  File "C:\Users\Cells\AppData\Local\Programs\Python\Python310\lib\unittest\loader.py", line 436, in _find_test_path
    module = self._get_module_from_name(name)
  File "C:\Users\Cells\AppData\Local\Programs\Python\Python310\lib\unittest\loader.py", line 377, in _get_module_from_name
    __import__(name)
  File "D:\aspose\cells\cloud\sdk-python\test\test_cells_unlock_api.py", line 12, in <module>
    import asposecellscloud
  File "D:\aspose\cells\cloud\sdk-python\asposecellscloud\__init__.py", line 27, in <module>
    from .models.above_average import AboveAverage
  File "D:\aspose\cells\cloud\sdk-python\asposecellscloud\models\__init__.py", line 27, in <module>
    from .above_average import AboveAverage
  File "D:\aspose\cells\cloud\sdk-python\asposecellscloud\models\above_average.py", line 25, in <module>
    from six import iteritems
ModuleNotFoundError: No module named 'six'

]]></error>
	</testcase>
	<testcase classname="unittest.loader._FailedTest" name="test_cells_watermark_api" time="0.000">
		<error type="ImportError" message="Failed to import test module: test.test_cells_watermark_api
Traceback (most recent call last):
  File &quot;C:\Users\Cells\AppData\Local\Programs\Python\Python310\lib\unittest\loader.py&quot;, line 436, in _find_test_path
    module = self._get_module_from_name(name)
  File &quot;C:\Users\Cells\AppData\Local\Programs\Python\Python310\lib\unittest\loader.py&quot;, line 377, in _get_module_from_name
    __import__(name)
  File &quot;D:\aspose\cells\cloud\sdk-python\test\test_cells_watermark_api.py&quot;, line 12, in &lt;module&gt;
    import asposecellscloud
  File &quot;D:\aspose\cells\cloud\sdk-python\asposecellscloud\__init__.py&quot;, line 27, in &lt;module&gt;
    from .models.above_average import AboveAverage
  File &quot;D:\aspose\cells\cloud\sdk-python\asposecellscloud\models\__init__.py&quot;, line 27, in &lt;module&gt;
    from .above_average import AboveAverage
  File &quot;D:\aspose\cells\cloud\sdk-python\asposecellscloud\models\above_average.py&quot;, line 25, in &lt;module&gt;
    from six import iteritems
ModuleNotFoundError: No module named 'six'
"><![CDATA[ImportError: Failed to import test module: test.test_cells_watermark_api
Traceback (most recent call last):
  File "C:\Users\Cells\AppData\Local\Programs\Python\Python310\lib\unittest\loader.py", line 436, in _find_test_path
    module = self._get_module_from_name(name)
  File "C:\Users\Cells\AppData\Local\Programs\Python\Python310\lib\unittest\loader.py", line 377, in _get_module_from_name
    __import__(name)
  File "D:\aspose\cells\cloud\sdk-python\test\test_cells_watermark_api.py", line 12, in <module>
    import asposecellscloud
  File "D:\aspose\cells\cloud\sdk-python\asposecellscloud\__init__.py", line 27, in <module>
    from .models.above_average import AboveAverage
  File "D:\aspose\cells\cloud\sdk-python\asposecellscloud\models\__init__.py", line 27, in <module>
    from .above_average import AboveAverage
  File "D:\aspose\cells\cloud\sdk-python\asposecellscloud\models\above_average.py", line 25, in <module>
    from six import iteritems
ModuleNotFoundError: No module named 'six'

]]></error>
	</testcase>
	<testcase classname="unittest.loader._FailedTest" name="test_cells_workbook_api" time="0.000">
		<error type="ImportError" message="Failed to import test module: test.test_cells_workbook_api
Traceback (most recent call last):
  File &quot;C:\Users\Cells\AppData\Local\Programs\Python\Python310\lib\unittest\loader.py&quot;, line 436, in _find_test_path
    module = self._get_module_from_name(name)
  File &quot;C:\Users\Cells\AppData\Local\Programs\Python\Python310\lib\unittest\loader.py&quot;, line 377, in _get_module_from_name
    __import__(name)
  File &quot;D:\aspose\cells\cloud\sdk-python\test\test_cells_workbook_api.py&quot;, line 23, in &lt;module&gt;
    import asposecellscloud
  File &quot;D:\aspose\cells\cloud\sdk-python\asposecellscloud\__init__.py&quot;, line 27, in &lt;module&gt;
    from .models.above_average import AboveAverage
  File &quot;D:\aspose\cells\cloud\sdk-python\asposecellscloud\models\__init__.py&quot;, line 27, in &lt;module&gt;
    from .above_average import AboveAverage
  File &quot;D:\aspose\cells\cloud\sdk-python\asposecellscloud\models\above_average.py&quot;, line 25, in &lt;module&gt;
    from six import iteritems
ModuleNotFoundError: No module named 'six'
"><![CDATA[ImportError: Failed to import test module: test.test_cells_workbook_api
Traceback (most recent call last):
  File "C:\Users\Cells\AppData\Local\Programs\Python\Python310\lib\unittest\loader.py", line 436, in _find_test_path
    module = self._get_module_from_name(name)
  File "C:\Users\Cells\AppData\Local\Programs\Python\Python310\lib\unittest\loader.py", line 377, in _get_module_from_name
    __import__(name)
  File "D:\aspose\cells\cloud\sdk-python\test\test_cells_workbook_api.py", line 23, in <module>
    import asposecellscloud
  File "D:\aspose\cells\cloud\sdk-python\asposecellscloud\__init__.py", line 27, in <module>
    from .models.above_average import AboveAverage
  File "D:\aspose\cells\cloud\sdk-python\asposecellscloud\models\__init__.py", line 27, in <module>
    from .above_average import AboveAverage
  File "D:\aspose\cells\cloud\sdk-python\asposecellscloud\models\above_average.py", line 25, in <module>
    from six import iteritems
ModuleNotFoundError: No module named 'six'

]]></error>
	</testcase>
	<testcase classname="unittest.loader._FailedTest" name="test_cells_worksheet_validations_api" time="0.000">
		<error type="ImportError" message="Failed to import test module: test.test_cells_worksheet_validations_api
Traceback (most recent call last):
  File &quot;C:\Users\Cells\AppData\Local\Programs\Python\Python310\lib\unittest\loader.py&quot;, line 436, in _find_test_path
    module = self._get_module_from_name(name)
  File &quot;C:\Users\Cells\AppData\Local\Programs\Python\Python310\lib\unittest\loader.py&quot;, line 377, in _get_module_from_name
    __import__(name)
  File &quot;D:\aspose\cells\cloud\sdk-python\test\test_cells_worksheet_validations_api.py&quot;, line 23, in &lt;module&gt;
    import asposecellscloud
  File &quot;D:\aspose\cells\cloud\sdk-python\asposecellscloud\__init__.py&quot;, line 27, in &lt;module&gt;
    from .models.above_average import AboveAverage
  File &quot;D:\aspose\cells\cloud\sdk-python\asposecellscloud\models\__init__.py&quot;, line 27, in &lt;module&gt;
    from .above_average import AboveAverage
  File &quot;D:\aspose\cells\cloud\sdk-python\asposecellscloud\models\above_average.py&quot;, line 25, in &lt;module&gt;
    from six import iteritems
ModuleNotFoundError: No module named 'six'
"><![CDATA[ImportError: Failed to import test module: test.test_cells_worksheet_validations_api
Traceback (most recent call last):
  File "C:\Users\Cells\AppData\Local\Programs\Python\Python310\lib\unittest\loader.py", line 436, in _find_test_path
    module = self._get_module_from_name(name)
  File "C:\Users\Cells\AppData\Local\Programs\Python\Python310\lib\unittest\loader.py", line 377, in _get_module_from_name
    __import__(name)
  File "D:\aspose\cells\cloud\sdk-python\test\test_cells_worksheet_validations_api.py", line 23, in <module>
    import asposecellscloud
  File "D:\aspose\cells\cloud\sdk-python\asposecellscloud\__init__.py", line 27, in <module>
    from .models.above_average import AboveAverage
  File "D:\aspose\cells\cloud\sdk-python\asposecellscloud\models\__init__.py", line 27, in <module>
    from .above_average import AboveAverage
  File "D:\aspose\cells\cloud\sdk-python\asposecellscloud\models\above_average.py", line 25, in <module>
    from six import iteritems
ModuleNotFoundError: No module named 'six'

]]></error>
	</testcase>
	<testcase classname="unittest.loader._FailedTest" name="test_cells_worksheets_api" time="0.000">
		<error type="ImportError" message="Failed to import test module: test.test_cells_worksheets_api
Traceback (most recent call last):
  File &quot;C:\Users\Cells\AppData\Local\Programs\Python\Python310\lib\unittest\loader.py&quot;, line 436, in _find_test_path
    module = self._get_module_from_name(name)
  File &quot;C:\Users\Cells\AppData\Local\Programs\Python\Python310\lib\unittest\loader.py&quot;, line 377, in _get_module_from_name
    __import__(name)
  File &quot;D:\aspose\cells\cloud\sdk-python\test\test_cells_worksheets_api.py&quot;, line 23, in &lt;module&gt;
    import asposecellscloud
  File &quot;D:\aspose\cells\cloud\sdk-python\asposecellscloud\__init__.py&quot;, line 27, in &lt;module&gt;
    from .models.above_average import AboveAverage
  File &quot;D:\aspose\cells\cloud\sdk-python\asposecellscloud\models\__init__.py&quot;, line 27, in &lt;module&gt;
    from .above_average import AboveAverage
  File &quot;D:\aspose\cells\cloud\sdk-python\asposecellscloud\models\above_average.py&quot;, line 25, in &lt;module&gt;
    from six import iteritems
ModuleNotFoundError: No module named 'six'
"><![CDATA[ImportError: Failed to import test module: test.test_cells_worksheets_api
Traceback (most recent call last):
  File "C:\Users\Cells\AppData\Local\Programs\Python\Python310\lib\unittest\loader.py", line 436, in _find_test_path
    module = self._get_module_from_name(name)
  File "C:\Users\Cells\AppData\Local\Programs\Python\Python310\lib\unittest\loader.py", line 377, in _get_module_from_name
    __import__(name)
  File "D:\aspose\cells\cloud\sdk-python\test\test_cells_worksheets_api.py", line 23, in <module>
    import asposecellscloud
  File "D:\aspose\cells\cloud\sdk-python\asposecellscloud\__init__.py", line 27, in <module>
    from .models.above_average import AboveAverage
  File "D:\aspose\cells\cloud\sdk-python\asposecellscloud\models\__init__.py", line 27, in <module>
    from .above_average import AboveAverage
  File "D:\aspose\cells\cloud\sdk-python\asposecellscloud\models\above_average.py", line 25, in <module>
    from six import iteritems
ModuleNotFoundError: No module named 'six'

]]></error>
	</testcase>
	<system-out><![CDATA[]]></system-out>
	<system-err><![CDATA[]]></system-err>
</testsuite>
